Workbook

Sheet Weekly Return
B2: Bedstone Farm | C2: Bedstone Poultry Ltd | D2: 0 | E2: Avara Foods - Broiler Weekly Return | L2: Table | M2: 1 | N2: of | O2: 9
B3: BEDS | C3: 3009 | D3: 0
B4: 3008 | C4: BEDS | D4: 0
B5: 24/02/2026 | D5: 0
B6: Ross 308 | C6: Birds placed | D6: 0 | E6: ='Placement Information'!$I$15 -> 0 | F6: ='Placement Information'!$O$15 -> 0 | G6: ='Placement Information'!$U$15 -> 0 | H6: ='Placement Information'!$C$28 -> 0 | I6: ='Placement Information'!$I$28 -> 0 | J6: ='Placement Information'!$O$28 -> 0 | K6: ='Placement Information'!$U$28 -> 0 | L6: ='Placement Information'!$C$41 -> 0 | M6: ='Placement Information'!$I$41 -> 0 | N6: ='Placement Information'!$O$41 -> 0 | O6: ='Placement Information'!$U$41 -> 0 | P6: ='Placement Information'!$C$54 -> 0 | Q6: ='Placement Information'!$I$54 -> 0 | R6: ='Placement Information'!$O$54 -> 0
B7: Avara | C7: Breed | D7: 0 | E7: ='Placement Information'!$J$6 -> Ross 308 | F7: ='Placement Information'!$P$6 -> Ross 308 | G7: ='Placement Information'!$V$6 -> Ross 308 | H7: ='Placement Information'!$D$19 -> Ross 308 | I7: ='Placement Information'!$J$19 -> Ross 308 | J7: ='Placement Information'!$P$19 -> Ross 308 | K7: ='Placement Information'!$V$19 -> Ross 308 | L7: ='Placement Information'!$D$32 -> 0 | M7: ='Placement Information'!$J$32 -> 0 | N7: ='Placement Information'!$P$32 -> 0 | O7: ='Placement Information'!$V$32 -> 0 | P7: ='Placement Information'!$D$45 -> 0 | Q7: ='Placement Information'!$J$45 -> 0 | R7: ='Placement Information'!$P$45 -> 0
B8: DAY_3 | D8: 0
C9: House | D9: 0 | E9: 2 | F9: 3 | G9: 4 | H9: 5 | I9: 6 | J9: 7 | K9: 8 | L9: 9 | M9: 10 | N9: 11 | O9: 12 | P9: 13 | Q9: 14 | R9: 15
C10: Age (days) | D10: 3 | E10: 3 | F10: 3 | G10: 3 | H10: 3 | I10: 3 | J10: 3 | K10: 3 | L10: 3 | M10: 3 | N10: 3 | O10: 3 | P10: 3 | Q10: 3 | R10: 3
B11: 0 to 3 days | C11: Mortality (excluding culls)
A12: House 1 | B12: 0 | C12: 0 | D12: 0 | E12: 0 | F12: 0 | G12: 0 | H12: 0 | I12: 0
A13: House 2 | B13: 0 | C13: 0 | D13: 0 | E13: 0 | F13: 0 | G13: 0 | H13: 0 | I13: 0
C15: CDMR % | R15: =SUM(D15:K15)/8 -> 0
F17: General Comments
B18: The above information should be provided when youngest birds reach 3 days
B19: by e-mail to agriculture.planning@avarafoods.co.uk & your area manager
B28: Site: | C28: =+C2 -> Bedstone Poultry Ltd | E28: Avara Foods - Broiler Weekly Return | L28: Table | M28: 2 | N28: of | O28: 9
B29: Crop: | C29: =+C3 -> 3009
B30: Farm Code: | C30: =+C4 -> NaN
C32: Birds placed | D32: ='Placement Information'!$C$15 -> 0 | E32: ='Placement Information'!$I$15 -> 0 | F32: ='Placement Information'!$O$15 -> 0 | G32: ='Placement Information'!$U$15 -> 0 | H32: ='Placement Information'!$C$28 -> 0 | I32: ='Placement Information'!$I$28 -> 0 | J32: ='Placement Information'!$O$28 -> 0 | K32: ='Placement Information'!$U$28 -> 0 | L32: ='Placement Information'!$C$41 -> 0 | M32: ='Placement Information'!$I$41 -> 0 | N32: ='Placement Information'!$O$41 -> 0 | O32: ='Placement Information'!$U$41 -> 0 | P32: ='Placement Information'!$C$54 -> 0 | Q32: ='Placement Information'!$I$54 -> 0 | R32: ='Placement Information'!$O$54 -> 0
C33: Breed | D33: ='Placement Information'!$D$6 -> Ross 308 | E33: ='Placement Information'!$J$6 -> Ross 308 | F33: ='Placement Information'!$P$6 -> Ross 308 | G33: ='Placement Information'!$V$6 -> Ross 308 | H33: ='Placement Information'!$D$19 -> Ross 308 | I33: ='Placement Information'!$J$19 -> Ross 308 | J33: ='Placement Information'!$P$19 -> Ross 308 | K33: ='Placement Information'!$V$19 -> Ross 308 | L33: ='Placement Information'!$D$32 -> 0 | M33: ='Placement Information'!$J$32 -> 0 | N33: ='Placement Information'!$P$32 -> 0 | O33: ='Placement Information'!$V$32 -> 0 | P33: ='Placement Information'!$D$45 -> 0 | Q33: ='Placement Information'!$J$45 -> 0 | R33: ='Placement Information'!$P$45 -> 0
C35: House | D35: 1 | E35: 2 | F35: 3 | G35: 4 | H35: 5 | I35: 6 | J35: 7 | K35: 8 | L35: 9 | M35: 10 | N35: 11 | O35: 12 | P35: 13 | Q35: 14 | R35: 15
C36: Age (days) | D36: 7 | E36: 7 | F36: 7 | G36: 7 | H36: 7 | I36: 7 | J36: 7 | K36: 7 | L36: 7 | M36: 7 | N36: 7 | O36: 7 | P36: 7 | Q36: 7 | R36: 7
B37: 4 to 7 days | C37: Mortality (excluding culls)
B38: 4 to 7 days | C38: Leg culls
B39: 4 to 7 days | C39: Other culls
B40: At 7 days | C40: Average weight (kg)
C42: % Growth vs. Avara Standard | D42: =D40/(VLOOKUP(D36,Standards!$A:$B,2,FALSE)) -> 0 | E42: =E40/(VLOOKUP(E36,Standards!$A:$B,2,FALSE)) -> 0 | F42: =F40/(VLOOKUP(F36,Standards!$A:$B,2,FALSE)) -> 0 | G42: =G40/(VLOOKUP(G36,Standards!$A:$B,2,FALSE)) -> 0 | H42: =H40/(VLOOKUP(H36,Standards!$A:$B,2,FALSE)) -> 0 | I42: =I40/(VLOOKUP(I36,Standards!$A:$B,2,FALSE)) -> 0 | J42: =J40/(VLOOKUP(J36,Standards!$A:$B,2,FALSE)) -> 0 | K42: =K40/(VLOOKUP(K36,Standards!$A:$B,2,FALSE)) -> 0 | ... R42: =R40/(VLOOKUP(R36,Standards!$A:$B,2,FALSE)) -> 0
C43: CDMR % | R43: =SUM(D43:K43)/8 -> 0
B45: Birds need to be weighed at 7 days | F45: General Comments
B46: The above information should be provided when youngest birds reach 7 days
B47: by e-mail to agriculture.planning@avarafoods.co.uk & your area manager
B56: Site: | C56: =C2 -> Bedstone Poultry Ltd | E56: Avara Foods - Broiler Weekly Return | L56: Table | M56: 3 | N56: of | O56: 9
B57: Crop: | C57: =C3 -> 3009
B58: Farm Code: | C58: =C4 -> NaN
C60: Birds placed | D60: ='Placement Information'!$C$15 -> 0 | E60: ='Placement Information'!$I$15 -> 0 | F60: ='Placement Information'!$O$15 -> 0 | G60: ='Placement Information'!$U$15 -> 0 | H60: ='Placement Information'!$C$28 -> 0 | I60: ='Placement Information'!$I$28 -> 0 | J60: ='Placement Information'!$O$28 -> 0 | K60: ='Placement Information'!$U$28 -> 0 | L60: ='Placement Information'!$C$41 -> 0 | M60: ='Placement Information'!$I$41 -> 0 | N60: ='Placement Information'!$O$41 -> 0 | O60: ='Placement Information'!$U$41 -> 0 | P60: ='Placement Information'!$C$54 -> 0 | Q60: ='Placement Information'!$I$54 -> 0 | R60: ='Placement Information'!$O$54 -> 0
C61: Breed | D61: ='Placement Information'!$D$6 -> Ross 308 | E61: ='Placement Information'!$J$6 -> Ross 308 | F61: ='Placement Information'!$P$6 -> Ross 308 | G61: ='Placement Information'!$V$6 -> Ross 308 | H61: ='Placement Information'!$D$19 -> Ross 308 | I61: ='Placement Information'!$J$19 -> Ross 308 | J61: ='Placement Information'!$P$19 -> Ross 308 | K61: ='Placement Information'!$V$19 -> Ross 308 | L61: ='Placement Information'!$D$32 -> 0 | M61: ='Placement Information'!$J$32 -> 0 | N61: ='Placement Information'!$P$32 -> 0 | O61: ='Placement Information'!$V$32 -> 0 | P61: ='Placement Information'!$D$45 -> 0 | Q61: ='Placement Information'!$J$45 -> 0 | R61: ='Placement Information'!$P$45 -> 0
C63: House | D63: 1 | E63: 2 | F63: 3 | G63: 4 | H63: 5 | I63: 6 | J63: 7 | K63: 8 | L63: 9 | M63: 10 | N63: 11 | O63: 12 | P63: 13 | Q63: 14 | R63: 15
C64: Age (days) | D64: 14 | E64: 14 | F64: 14 | G64: 14 | H64: 14 | I64: 14 | J64: 14 | K64: 14 | L64: 14 | M64: 14 | N64: 14 | O64: 14 | P64: 14 | Q64: 14 | R64: 14
B65: 8 to 14 days | C65: Mortality (excluding culls)
...

Sheet 35 day weights
A4: Site: | B4: ='Weekly Return'!C2 -> Bedstone Poultry Ltd | D4: Avara Foods - Broiler Weekly Return | K4: Table | L4: 5 | M4: of | N4: 8
A5: Crop: | B5: ='Weekly Return'!C3 -> 3009
A6: Farm Code: | B6: ='Weekly Return'!C4 -> NaN
B8: House | C8: 1 | D8: 2 | E8: 3 | F8: 4 | G8: 5 | H8: 6 | I8: 7 | J8: 8 | K8: 9 | L8: 10 | M8: 11 | N8: 12 | O8: 13 | P8: 14 | Q8: 15
B9: Age (days) | C9: 35 | D9: 35 | E9: 35 | F9: 35 | G9: 35 | H9: 35 | I9: 35 | J9: 35 | K9: 35 | L9: 35 | M9: 35 | N9: 35 | O9: 35 | P9: 35 | Q9: 35
A10: At 26 Days | B10: Average weight (kg)
B12: % Growth vs. Avara Standard | C12: =C10/(VLOOKUP(C9,Standards!$A:$B,2,FALSE)) -> 0 | D12: =D10/(VLOOKUP(D9,Standards!$A:$B,2,FALSE)) -> 0 | E12: =E10/(VLOOKUP(E9,Standards!$A:$B,2,FALSE)) -> 0 | F12: =F10/(VLOOKUP(F9,Standards!$A:$B,2,FALSE)) -> 0 | G12: =G10/(VLOOKUP(G9,Standards!$A:$B,2,FALSE)) -> 0 | H12: =H10/(VLOOKUP(H9,Standards!$A:$B,2,FALSE)) -> 0 | I12: =I10/(VLOOKUP(I9,Standards!$A:$B,2,FALSE)) -> 0 | J12: =J10/(VLOOKUP(J9,Standards!$A:$B,2,FALSE)) -> 0 | ... Q12: =Q10/(VLOOKUP(Q9,Standards!$A:$B,2,FALSE)) -> 0
B13: Predicted growth % into factory
A15: Birds need to be weighed at 35 days + predicted for factory | E15: General Comments
A16: The above information should be provided when each shed reaches 35 days
A17: by e-mail to agriculture.planning@avarafoods.co.uk & your area manager

Sheet Placement Information
B2: Farm Name: | C2: Bedstone Poultry Ltd
B5: First Date Placed | D5: 46077 | H5: First Date Placed | J5: =SUM(D5) -> 46077 | N5: First Date Placed | P5: =SUM(J5) -> 46077 | T5: First Date Placed | V5: =SUM(P5) -> 46077
B6: Shed 1 | C6: Breed | D6: Ross 308 | H6: Shed 2 | I6: Breed | J6: Ross 308 | N6: Shed 3 | O6: Breed | P6: Ross 308 | T6: Shed 4 | U6: Breed | V6: Ross 308 | AA6: HATCHERIES
B7: PTC No. | C7: Chicks | D7: Parent Age | E7: Flock | F7: Hatchery | H7: PTC No. | I7: Chicks | J7: Parent Age | K7: Flock | L7: Hatchery | N7: PTC No. | O7: Chicks | P7: Parent Age | Q7: Flock | R7: Hatchery | T7: PTC No. | U7: Chicks | V7: Parent Age | W7: Flock | X7: Hatchery | AA7: Aviagen
AA8: Annyalla
AA9: Caynham
AA10: Hooks
AA11: OTH
AA12: Ower
AA13: Quainton
AA14: Rayne
B15: TOTAL | C15: =SUM(C8:C14) -> 0 | H15: TOTAL | I15: =SUM(I8:I14) -> 0 | N15: TOTAL | O15: =SUM(O8:O14) -> 0 | T15: TOTAL | U15: =SUM(U8:U14) -> 0 | AA15: Shobdon
AA16: Usselby
B18: First Date Placed | D18: =SUM(V5) -> 46077 | H18: First Date Placed | J18: =SUM(D18) -> 46077 | N18: First Date Placed | P18: =SUM(J18) -> 46077 | T18: First Date Placed | V18: =SUM(P18) -> 46077
B19: Shed 5 | C19: Breed | D19: Ross 308 | H19: Shed 6 | I19: Breed | J19: Ross 308 | N19: Shed 7 | O19: Breed | P19: Ross 308 | T19: Shed 8 | U19: Breed | V19: Ross 308
B20: PTC No. | C20: Chicks | D20: Parent Age | E20: Flock | F20: Hatchery | H20: PTC No. | I20: Chicks | J20: Parent Age | K20: Flock | L20: Hatchery | N20: PTC No. | O20: Chicks | P20: Parent Age | Q20: Flock | R20: Hatchery | T20: PTC No. | U20: Chicks | V20: Parent Age | W20: Flock | X20: Hatchery
B28: TOTAL | C28: =SUM(C21:C27) -> 0 | H28: TOTAL | I28: =SUM(I21:I27) -> 0 | N28: TOTAL | O28: =SUM(O21:O27) -> 0 | T28: TOTAL | U28: =SUM(U21:U27) -> 0
B31: First Date Placed | H31: First Date Placed | N31: First Date Placed | T31: First Date Placed
B32: Shed 9 | C32: Breed | H32: Shed 10 | I32: Breed | N32: Shed 11 | O32: Breed | T32: Shed 12 | U32: Breed
B33: PTC No. | C33: Chicks | D33: Parent Age | E33: Flock | F33: Hatchery | H33: PTC No. | I33: Chicks | J33: Parent Age | K33: Flock | L33: Hatchery | N33: PTC No. | O33: Chicks | P33: Parent Age | Q33: Flock | R33: Hatchery | T33: PTC No. | U33: Chicks | V33: Parent Age | W33: Flock | X33: Hatchery
B41: TOTAL | C41: =SUM(C34:C40) -> 0 | H41: TOTAL | I41: =SUM(I34:I40) -> 0 | N41: TOTAL | O41: =SUM(O34:O40) -> 0 | T41: TOTAL | U41: =SUM(U34:U40) -> 0
B44: First Date Placed | H44: First Date Placed | N44: First Date Placed
B45: Shed 13 | C45: Breed | H45: Shed 14 | I45: Breed | N45: Shed 15 | O45: Breed
B46: PTC No. | C46: Chicks | D46: Parent Age | E46: Flock | F46: Hatchery | H46: PTC No. | I46: Chicks | J46: Parent Age | K46: Flock | L46: Hatchery | N46: PTC No. | O46: Chicks | P46: Parent Age | Q46: Flock | R46: Hatchery
B54: TOTAL | C54: =SUM(C47:C53) -> 0 | H54: TOTAL | I54: =SUM(I47:I53) -> 0 | N54: TOTAL | O54: =SUM(O47:O53) -> 0

Sheet Standards
A1: 7 | B1: 0.188 | E1: Litter destination drop down
A2: 14 | B2: 0.49 | E2: Select option from dropdown list
A3: 21 | B3: 0.975 | E3: % Litter retained on your farm and spread to land
A4: 26 | B4: 1.362 | E4: % Litter used in own AD plant
A5: 28 | B5: 1.535 | E5: % Litter sold to an external business e.g. Gamber
A6: 30 | B6: 1.718 | E6: % Litter sold to a local farm within the River Wye and Lugg catchment and spread to land
A7: 35 | B7: 2.194 | E7: % Litter sold to a local farm outside the River Wye and Lugg catchment and spread to land
E8: % Litter used in a litter burner

Sheet Instructions
B2: Placement information | L2: Weekly Return | AA2: Crop End Information
B3: This tab is to be filled in when chicks are first placed on farm | L3: General information | AA3: Located at the bottom of the Weekly return
B4: Information required for each shed: | L4: Following information fields to be filled in: | AA4: Crop End mortalities pull through automatically
B5: - Date first placed | L5: - Site (Farm name) Cell E5 | AA5: If you think these are incorrect, please inform us
B6: - Breed | L6: - Crop (Number) Cell E6 | AA6: CDMR DOES need to be input
B7: - PTC number | L7: - Farm Code (As on MTech) Cell E7
B8: - Number of Chicks | L8: Once this information is entered, it will automatically populate in the below pages | AA8: Information required for Feed
B9: - Parent Age | L9: Please get in touch if you are unsure of your farm code – it is a 4 letter code. | AA9: - Opening Stock (Feed used from Store)
B10: - Flock Code | AA10: - Feed Delivered
B11: - Hatchery (drop down list) | L11: 3 day information | AA11: - Feed Transferred between sites
B12: For example: | L12: Information to be filled in for each shed | AA12: - If feed has been transferred, you must specify where
L13: - Total mortality between 0-3 days | AA13: - Feed to store for this crop (Closing Stock)
L14: - Leg culls between 0-3 days | AA14: - Own Wheat Used
L15: - Other culls between 0-3 days
L16: - CDMR % | AA16: Feed used and Total feed + wheat will calculate automatcially
L18: 7 day information | AA18: Information required for Litter
L19: Information to be filled in for each shed | AA19: - Total litter quantity produced from the PREVIOUS crop
L20: - Total mortality between 4-7 days | AA20: - Select from the dropdown list the litter destination
L21: - Leg culls between 4-7 days | AA21: - If necessary, select a second destination for the litter
L22: - Other culls between 4-7 days | AA22: - Enter the % of litter from the total produced to the destination
L23: - Average weight (in KG)
L24: - CDMR %
L25: % growth index will be calculated automatically | AA25: Information required for Medication usage
AA26: Headings in the table to be filled out as per the example below:
L27: 14 day information | AA27: Date started | AB27: House Number | AC27: Number of Birds | AD27: Bird age on first day of medication | AE27: Medication Name | AF27: Medication Pack Size | AG27: Total Number of Packs Administered | AH27: Total number of days Medicated
L28: Information to be filled in for each shed | AA28: 44239 | AB28: 1 | AC28: 35000 | AD28: 22 | AE28: Amoxinsol | AF28: 200g | AG28: 6 | AH28: 3
L29: - Total mortality between 7-14 days | AA29: EXAMPLE
L30: - Leg culls between 7-14 days
L31: - Other culls between 7-14 days
L32: - Average weight (in KG) | AA32: Information to be sent to
L33: - CDMR % | AA33: Agriculture.planning@avarafoods.co.uk
L34: % growth index will be calculated automatically | AA34: Broiler-accounts@avarafoods.co.uk
AA35: Once the whole farm has been depopulated
L36: 21 day information
L37: Information to be filled in for each shed
L38: - Total mortality between 15-21 days
L39: - Leg culls between 15-21 days
L40: - Other culls between 15-21 days
L41: - Average weight (in KG)
L42: - CDMR %
...

Sheet Deadlines
B2: Placing All Sheds on The Same Day | M2: Placing Sheds over Multiple Days
B4: Information to be sent in on the day that birds turn the required age | M4: Up to 21 days:
B5: BY 2PM | M5: Information to be sent in for all sheds when the YOUNGEST birds reach the required age
M6: BY 2PM
B7: For Example:
B8: The day your birds turn 7, please send in the 7 day information | M8: For Example:
M9: If shed 1 turns 7 days on Monday and shed 2 turns 7 days on Tuesday, Send the weekly return in on the Tuesday
B11: IF INFORMATION IS DUE IN ON A FRIDAY PLEASE SEND NO LATER THAN
B12: 11AM
M13: 26,28 and 35 day returns:
B14: Weekly return to be sent to: | M14: Information to be sent in when each shed reaches the required age
B15: Agriculture.planning@avarafoods.co.uk and your Area Manager | M15: BY 2PM
M16: UNLESS WEIGHTS FALL ON A FRIDAY IN WHICH CASE
M17: 11AM
M20: For Example:
Q22: 26 days on | R22: Weekly return due
P23: Shed 1 | Q23: Monday | R23: Monday
P24: Shed 2 | Q24: Tuesday | R24: Tuesday
P25: Shed 3 | Q25: Wednesday | R25: Wednesday
M29: Weekly return to be sent to:
M30: Agriculture.planning@avarafoods.co.uk and your Area Manager
